Workbook

Sheet Estimates of the use of water (
A1: name | B1: year | C1: pop_n | D1: pop_u | E1: wat_bas_n | F1: wat_lim_n | G1: wat_unimp_n | H1: wat_sur_n | I1: wat_bas_r | J1: wat_lim_r | K1: wat_unimp_r | L1: wat_sur_r | M1: wat_bas_u | N1: wat_lim_u | O1: wat_unimp_u | P1: wat_sur_u | Q1: y_diff | R1: ARC_n | S1: ARC_r | T1: ARC_u | U1: wat_bas_n(rounded) | V1: wat_bas_r(rounded) | W1: wat_bas_u(rounded) | X1: ARC_n_full | Y1: ARC_r_full | Z1: ARC_u_full | AA1: ARC_diff | AB1: Region
A2: Afghanistan | B2: 2015 | C2: 34413.602 | D2: 24.802999 | E2: 61.339781 | F2: 3.5111995 | G2: 22.168784 | H2: 12.980236 | I2: 52.988502 | J2: 3.8611366 | K2: 26.553268 | L2: 16.597094 | M2: 86.658941 | N2: 2.4502706 | O2: 8.8760357 | P2: 2.014753 | Q2: =IF(A3=A2,B3-B2,"") -> 5 | R2: =IFERROR(IF($A3=$A2,($E3-$E2)/($B3-$B2),""),"null") -> 2.7503265 | S2: =IFERROR(IF($A3=$A2,($I3-$I2)/($B3-$B2),""),"null") -> 2.6678826 | T2: =IFERROR(IF($A3=$A2,($M3-$M2)/($B3-$B2),""),"null") -> 2.6682119 | U2: =IFERROR(ROUND(E2,0),"null") -> 61 | V2: =IFERROR(ROUND(I2,0),"null") -> 53 | W2: =IFERROR(ROUND(M2,0),"null") -> 87 | X2: =IF(AND($A3=$A2,$U2=100,$U3=100),"fullaccesss","") | Y2: =IF(AND($A3=$A2,$V2=100,$V3=100),"fullaccesss","") | Z2: =IF(AND($A3=$A2,$W2=100,$W3=100),"fullaccesss","") | AA2: =IFERROR(IF(AND(S2<>"",T2<>""),S2-T2,""),"null") -> -0.000329218 | AB2: =LOOKUP($A2,Sheet2!$A$1:$B$233) -> #N/A
A3: Afghanistan | B3: 2020 | C3: 38928.34 | D3: 26.025999 | E3: 75.091413 | F3: 1.4475417 | G3: 14.560263 | H3: 8.9007822 | I3: 66.327915 | J3: 1.9568249 | K3: 19.682949 | L3: 12.032311 | M3: 100 | N3: 0 | O3: 0 | P3: 0 | Q3: =IF(A4=A3,B4-B3,"") | R3: =IFERROR(IF($A4=$A3,($E4-$E3)/($B4-$B3),""),"null") | S3: =IFERROR(IF($A4=$A3,($I4-$I3)/($B4-$B3),""),"null") | T3: =IFERROR(IF($A4=$A3,($M4-$M3)/($B4-$B3),""),"null") | U3: =IFERROR(ROUND(E3,0),"null") -> 75 | V3: =IFERROR(ROUND(I3,0),"null") -> 66 | W3: =IFERROR(ROUND(M3,0),"null") -> 100 | X3: =IF(AND($A4=$A3,$U3=100,$U4=100),"fullaccesss","") | Y3: =IF(AND($A4=$A3,$V3=100,$V4=100),"fullaccesss","") | Z3: =IF(AND($A4=$A3,$W3=100,$W4=100),"fullaccesss","") | AA3: =IFERROR(IF(AND(S3<>"",T3<>""),S3-T3,""),"null") | AB3: =LOOKUP($A3,Sheet2!$A$1:$B$233) -> #N/A
A4: Albania | B4: 2015 | C4: 2890.5239 | D4: 57.433998 | E4: 93.394325 | F4: 3.6263837 | G4: 2.979291 | H4: 0 | I4: 90.627275 | J4: 5.2631726 | K4: 4.1095527 | L4: 0 | M4: 95.445067 | N4: 2.4133118 | O4: 2.1416212 | P4: 0 | Q4: =IF(A5=A4,B5-B4,"") -> 5 | R4: =IFERROR(IF($A5=$A4,($E5-$E4)/($B5-$B4),""),"null") -> 0.3347427 | S4: =IFERROR(IF($A5=$A4,($I5-$I4)/($B5-$B4),""),"null") -> 0.69281669 | T4: =IFERROR(IF($A5=$A4,($M5-$M4)/($B5-$B4),""),"null") -> 0.043748432 | U4: =IFERROR(ROUND(E4,0),"null") -> 93 | V4: =IFERROR(ROUND(I4,0),"null") -> 91 | W4: =IFERROR(ROUND(M4,0),"null") -> 95 | X4: =IF(AND($A5=$A4,$U4=100,$U5=100),"fullaccesss","") | Y4: =IF(AND($A5=$A4,$V4=100,$V5=100),"fullaccesss","") | Z4: =IF(AND($A5=$A4,$W4=100,$W5=100),"fullaccesss","") | AA4: =IFERROR(IF(AND(S4<>"",T4<>""),S4-T4,""),"null") -> 0.64906826 | AB4: =LOOKUP($A4,Sheet2!$A$1:$B$233) -> Europe & Central Asia
A5: Albania | B5: 2020 | C5: 2877.8 | D5: 62.112 | E5: 95.068039 | F5: 1.8846561 | G5: 3.0473051 | H5: 0 | I5: 94.091358 | J5: 2.305265 | K5: 3.603377 | L5: 0 | M5: 95.663809 | N5: 1.6280868 | O5: 2.7081041 | P5: 0 | Q5: =IF(A6=A5,B6-B5,"") | R5: =IFERROR(IF($A6=$A5,($E6-$E5)/($B6-$B5),""),"null") | S5: =IFERROR(IF($A6=$A5,($I6-$I5)/($B6-$B5),""),"null") | T5: =IFERROR(IF($A6=$A5,($M6-$M5)/($B6-$B5),""),"null") | U5: =IFERROR(ROUND(E5,0),"null") -> 95 | V5: =IFERROR(ROUND(I5,0),"null") -> 94 | W5: =IFERROR(ROUND(M5,0),"null") -> 96 | X5: =IF(AND($A6=$A5,$U5=100,$U6=100),"fullaccesss","") | Y5: =IF(AND($A6=$A5,$V5=100,$V6=100),"fullaccesss","") | Z5: =IF(AND($A6=$A5,$W5=100,$W6=100),"fullaccesss","") | AA5: =IFERROR(IF(AND(S5<>"",T5<>""),S5-T5,""),"null") | AB5: =LOOKUP($A5,Sheet2!$A$1:$B$233) -> Europe & Central Asia
A6: Algeria | B6: 2015 | C6: 39728.02 | D6: 70.848 | E6: 93.409562 | F6: 5.1577809 | G6: 1.2754647 | H6: 0.15719289 | I6: 88.352707 | J6: 8.6857531 | K6: 2.5804318 | L6: 0.38110822 | M6: 95.490315 | N6: 3.7061173 | O6: 0.73851009 | P6: 0.065057898 | Q6: =IF(A7=A6,B7-B6,"") -> 5 | R6: =IFERROR(IF($A7=$A6,($E7-$E6)/($B7-$B6),""),"null") -> 0.20555369 | S6: =IFERROR(IF($A7=$A6,($I7-$I6)/($B7-$B6),""),"null") -> 0.33696621 | T6: =IFERROR(IF($A7=$A6,($M7-$M6)/($B7-$B6),""),"null") -> 0.10288423 | U6: =IFERROR(ROUND(E6,0),"null") -> 93 | V6: =IFERROR(ROUND(I6,0),"null") -> 88 | W6: =IFERROR(ROUND(M6,0),"null") -> 95 | X6: =IF(AND($A7=$A6,$U6=100,$U7=100),"fullaccesss","") | Y6: =IF(AND($A7=$A6,$V6=100,$V7=100),"fullaccesss","") | Z6: =IF(AND($A7=$A6,$W6=100,$W7=100),"fullaccesss","") | AA6: =IFERROR(IF(AND(S6<>"",T6<>""),S6-T6,""),"null") -> 0.23408198 | AB6: =LOOKUP($A6,Sheet2!$A$1:$B$233) -> Middle East & North Africa
A7: Algeria | B7: 2020 | C7: 43851.043 | D7: 73.733002 | E7: 94.43733 | F7: 4.9858808 | G7: 0.53183666 | H7: 0.044952533 | I7: 90.037538 | J7: 8.7967221 | K7: 0.99460303 | L7: 0.17113693 | M7: 96.004736 | N7: 3.6282886 | O7: 0.36697555 | P7: 0 | Q7: =IF(A8=A7,B8-B7,"") | R7: =IFERROR(IF($A8=$A7,($E8-$E7)/($B8-$B7),""),"null") | S7: =IFERROR(IF($A8=$A7,($I8-$I7)/($B8-$B7),""),"null") | T7: =IFERROR(IF($A8=$A7,($M8-$M7)/($B8-$B7),""),"null") | U7: =IFERROR(ROUND(E7,0),"null") -> 94 | V7: =IFERROR(ROUND(I7,0),"null") -> 90 | W7: =IFERROR(ROUND(M7,0),"null") -> 96 | X7: =IF(AND($A8=$A7,$U7=100,$U8=100),"fullaccesss","") | Y7: =IF(AND($A8=$A7,$V7=100,$V8=100),"fullaccesss","") | Z7: =IF(AND($A8=$A7,$W7=100,$W8=100),"fullaccesss","") | AA7: =IFERROR(IF(AND(S7<>"",T7<>""),S7-T7,""),"null") | AB7: =LOOKUP($A7,Sheet2!$A$1:$B$233) -> Middle East & North Africa
A8: American Samoa | B8: 2015 | C8: 55.806 | D8: 87.238007 | E8: 99.619103 | F8: 0 | G8: 0.38089685 | H8: 0 | I8: null | J8: null | K8: null | L8: null | M8: null | N8: null | O8: null | P8: null | Q8: =IF(A9=A8,B9-B8,"") -> 5 | R8: =IFERROR(IF($A9=$A8,($E9-$E8)/($B9-$B8),""),"null") -> 0.030933702 | S8: =IFERROR(IF($A9=$A8,($I9-$I8)/($B9-$B8),""),"null") -> null | T8: =IFERROR(IF($A9=$A8,($M9-$M8)/($B9-$B8),""),"null") -> null | U8: =IFERROR(ROUND(E8,0),"null") -> 100 | V8: =IFERROR(ROUND(I8,0),"null") -> null | W8: =IFERROR(ROUND(M8,0),"null") -> null | X8: =IF(AND($A9=$A8,$U8=100,$U9=100),"fullaccesss","") -> fullaccesss | Y8: =IF(AND($A9=$A8,$V8=100,$V9=100),"fullaccesss","") | Z8: =IF(AND($A9=$A8,$W8=100,$W9=100),"fullaccesss","") | AA8: =IFERROR(IF(AND(S8<>"",T8<>""),S8-T8,""),"null") -> null | AB8: =LOOKUP($A8,Sheet2!$A$1:$B$233) -> East Asia & Pacific
A9: American Samoa | B9: 2020 | C9: 55.196999 | D9: 87.153 | E9: 99.773772 | F9: 0 | G9: 0.22622834 | H9: 0 | I9: null | J9: null | K9: null | L9: null | M9: null | N9: null | O9: null | P9: null | Q9: =IF(A10=A9,B10-B9,"") | R9: =IFERROR(IF($A10=$A9,($E10-$E9)/($B10-$B9),""),"null") | S9: =IFERROR(IF($A10=$A9,($I10-$I9)/($B10-$B9),""),"null") | T9: =IFERROR(IF($A10=$A9,($M10-$M9)/($B10-$B9),""),"null") | U9: =IFERROR(ROUND(E9,0),"null") -> 100 | V9: =IFERROR(ROUND(I9,0),"null") -> null | W9: =IFERROR(ROUND(M9,0),"null") -> null | X9: =IF(AND($A10=$A9,$U9=100,$U10=100),"fullaccesss","") | Y9: =IF(AND($A10=$A9,$V9=100,$V10=100),"fullaccesss","") | Z9: =IF(AND($A10=$A9,$W9=100,$W10=100),"fullaccesss","") | AA9: =IFERROR(IF(AND(S9<>"",T9<>""),S9-T9,""),"null") | AB9: =LOOKUP($A9,Sheet2!$A$1:$B$233) -> East Asia & Pacific
A10: Andorra | B10: 2015 | C10: 77.992996 | D10: 88.344994 | E10: 99.999998 | F10: 0 | G10: 2.4455384e-06 | H10: 0 | I10: 100 | J10: 0 | K10: 0 | L10: 0 | M10: 100 | N10: 0 | O10: 0 | P10: 0 | Q10: =IF(A11=A10,B11-B10,"") -> 5 | R10: =IFERROR(IF($A11=$A10,($E11-$E10)/($B11-$B10),""),"null") -> 1.23e-06 | S10: =IFERROR(IF($A11=$A10,($I11-$I10)/($B11-$B10),""),"null") -> 0 | T10: =IFERROR(IF($A11=$A10,($M11-$M10)/($B11-$B10),""),"null") -> 0 | U10: =IFERROR(ROUND(E10,0),"null") -> 100 | V10: =IFERROR(ROUND(I10,0),"null") -> 100 | W10: =IFERROR(ROUND(M10,0),"null") -> 100 | X10: =IF(AND($A11=$A10,$U10=100,$U11=100),"fullaccesss","") -> fullaccesss | Y10: =IF(AND($A11=$A10,$V10=100,$V11=100),"fullaccesss","") -> fullaccesss | Z10: =IF(AND($A11=$A10,$W10=100,$W11=100),"fullaccesss","") -> fullaccesss | AA10: =IFERROR(IF(AND(S10<>"",T10<>""),S10-T10,""),"null") -> 0 | AB10: =LOOKUP($A10,Sheet2!$A$1:$B$233) -> Europe & Central Asia
A11: Andorra | B11: 2020 | C11: 77.264999 | D11: 87.916 | E11: 100 | F11: 0 | G11: 0 | H11: 0 | I11: 100 | J11: 0 | K11: 0 | L11: 0 | M11: 100 | N11: 0 | O11: 0 | P11: 0 | Q11: =IF(A12=A11,B12-B11,"") | R11: =IFERROR(IF($A12=$A11,($E12-$E11)/($B12-$B11),""),"null") | S11: =IFERROR(IF($A12=$A11,($I12-$I11)/($B12-$B11),""),"null") | T11: =IFERROR(IF($A12=$A11,($M12-$M11)/($B12-$B11),""),"null") | U11: =IFERROR(ROUND(E11,0),"null") -> 100 | V11: =IFERROR(ROUND(I11,0),"null") -> 100 | W11: =IFERROR(ROUND(M11,0),"null") -> 100 | X11: =IF(AND($A12=$A11,$U11=100,$U12=100),"fullaccesss","") | Y11: =IF(AND($A12=$A11,$V11=100,$V12=100),"fullaccesss","") | Z11: =IF(AND($A12=$A11,$W11=100,$W12=100),"fullaccesss","") | AA11: =IFERROR(IF(AND(S11<>"",T11<>""),S11-T11,""),"null") | AB11: =LOOKUP($A11,Sheet2!$A$1:$B$233) -> Europe & Central Asia
A12: Angola | B12: 2015 | C12: 27884.381 | D12: 63.445995 | E12: 54.316928 | F12: 11.368619 | G12: 17.372356 | H12: 16.942097 | I12: 26.714369 | J12: 9.9310693 | K12: 21.725308 | L12: 41.629254 | M12: 70.219965 | N12: 12.196853 | O12: 14.864431 | P12: 2.7187499 | Q12: =IF(A13=A12,B13-B12,"") -> 5 | R12: =IFERROR(IF($A13=$A12,($E13-$E12)/($B13-$B12),""),"null") -> 0.57016185 | S12: =IFERROR(IF($A13=$A12,($I13-$I12)/($B13-$B12),""),"null") -> 0.21877144 | T12: =IFERROR(IF($A13=$A12,($M13-$M12)/($B13-$B12),""),"null") -> 0.3046367 | U12: =IFERROR(ROUND(E12,0),"null") -> 54 | V12: =IFERROR(ROUND(I12,0),"null") -> 27 | W12: =IFERROR(ROUND(M12,0),"null") -> 70 | X12: =IF(AND($A13=$A12,$U12=100,$U13=100),"fullaccesss","") | Y12: =IF(AND($A13=$A12,$V12=100,$V13=100),"fullaccesss","") | Z12: =IF(AND($A13=$A12,$W12=100,$W13=100),"fullaccesss","") | AA12: =IFERROR(IF(AND(S12<>"",T12<>""),S12-T12,""),"null") -> -0.085865258 | AB12: =LOOKUP($A12,Sheet2!$A$1:$B$233) -> Sub-Saharan Africa
A13: Angola | B13: 2020 | C13: 32866.27 | D13: 66.824997 | E13: 57.167738 | F13: 9.2873499 | G13: 19.450825 | H13: 14.094087 | I13: 27.808227 | J13: 8.7404884 | K13: 22.933153 | L13: 40.518132 | M13: 71.743149 | N13: 9.5588375 | O13: 17.722035 | P13: 0.97597916 | Q13: =IF(A14=A13,B14-B13,"") | R13: =IFERROR(IF($A14=$A13,($E14-$E13)/($B14-$B13),""),"null") | S13: =IFERROR(IF($A14=$A13,($I14-$I13)/($B14-$B13),""),"null") | T13: =IFERROR(IF($A14=$A13,($M14-$M13)/($B14-$B13),""),"null") | U13: =IFERROR(ROUND(E13,0),"null") -> 57 | V13: =IFERROR(ROUND(I13,0),"null") -> 28 | W13: =IFERROR(ROUND(M13,0),"null") -> 72 | X13: =IF(AND($A14=$A13,$U13=100,$U14=100),"fullaccesss","") | Y13: =IF(AND($A14=$A13,$V13=100,$V14=100),"fullaccesss","") | Z13: =IF(AND($A14=$A13,$W13=100,$W14=100),"fullaccesss","") | AA13: =IFERROR(IF(AND(S13<>"",T13<>""),S13-T13,""),"null") | AB13: =LOOKUP($A13,Sheet2!$A$1:$B$233) -> Sub-Saharan Africa
A14: Anguilla | B14: 2015 | C14: 14.279 | D14: 100 | E14: 97.482274 | F14: 0 | G14: 2.5177258 | H14: 0 | I14: null | J14: null | K14: null | L14: null | M14: 97.482274 | N14: 0 | O14: 2.5177258 | P14: 0 | Q14: =IF(A15=A14,B15-B14,"") -> 2 | R14: =IFERROR(IF($A15=$A14,($E15-$E14)/($B15-$B14),""),"null") -> 0 | S14: =IFERROR(IF($A15=$A14,($I15-$I14)/($B15-$B14),""),"null") -> null | T14: =IFERROR(IF($A15=$A14,($M15-$M14)/($B15-$B14),""),"null") -> 0 | U14: =IFERROR(ROUND(E14,0),"null") -> 97 | V14: =IFERROR(ROUND(I14,0),"null") -> null | W14: =IFERROR(ROUND(M14,0),"null") -> 97 | X14: =IF(AND($A15=$A14,$U14=100,$U15=100),"fullaccesss","") | Y14: =IF(AND($A15=$A14,$V14=100,$V15=100),"fullaccesss","") | Z14: =IF(AND($A15=$A14,$W14=100,$W15=100),"fullaccesss","") | AA14: =IFERROR(IF(AND(S14<>"",T14<>""),S14-T14,""),"null") -> null | AB14: =LOOKUP($A14,Sheet2!$A$1:$B$233) -> Latin America & Caribbean
A15: Anguilla | B15: 2017 | C15: 14.588 | D15: 100 | E15: 97.482274 | F15: 0 | G15: 2.5177258 | H15: 0 | I15: null | J15: null | K15: null | L15: null | M15: 97.482274 | N15: 0 | O15: 2.5177258 | P15: 0 | Q15: =IF(A16=A15,B16-B15,"") | R15: =IFERROR(IF($A16=$A15,($E16-$E15)/($B16-$B15),""),"null") | S15: =IFERROR(IF($A16=$A15,($I16-$I15)/($B16-$B15),""),"null") | T15: =IFERROR(IF($A16=$A15,($M16-$M15)/($B16-$B15),""),"null") | U15: =IFERROR(ROUND(E15,0),"null") -> 97 | V15: =IFERROR(ROUND(I15,0),"null") -> null | W15: =IFERROR(ROUND(M15,0),"null") -> 97 | X15: =IF(AND($A16=$A15,$U15=100,$U16=100),"fullaccesss","") | Y15: =IF(AND($A16=$A15,$V15=100,$V16=100),"fullaccesss","") | Z15: =IF(AND($A16=$A15,$W15=100,$W16=100),"fullaccesss","") | AA15: =IFERROR(IF(AND(S15<>"",T15<>""),S15-T15,""),"null") | AB15: =LOOKUP($A15,Sheet2!$A$1:$B$233) -> Latin America & Caribbean
A16: Antigua and Barbuda | B16: 2015 | C16: 93.570999 | D16: 25 | E16: 96.739186 | F16: 0 | G16: 3.1663476 | H16: 0.094466114 | I16: null | J16: null | K16: null | L16: null | M16: null | N16: null | O16: null | P16: null | Q16: =IF(A17=A16,B17-B16,"") -> 2 | R16: =IFERROR(IF($A17=$A16,($E17-$E16)/($B17-$B16),""),"null") -> 0 | S16: =IFERROR(IF($A17=$A16,($I17-$I16)/($B17-$B16),""),"null") -> null | T16: =IFERROR(IF($A17=$A16,($M17-$M16)/($B17-$B16),""),"null") -> null | U16: =IFERROR(ROUND(E16,0),"null") -> 97 | V16: =IFERROR(ROUND(I16,0),"null") -> null | W16: =IFERROR(ROUND(M16,0),"null") -> null | X16: =IF(AND($A17=$A16,$U16=100,$U17=100),"fullaccesss","") | Y16: =IF(AND($A17=$A16,$V16=100,$V17=100),"fullaccesss","") | Z16: =IF(AND($A17=$A16,$W16=100,$W17=100),"fullaccesss","") | AA16: =IFERROR(IF(AND(S16<>"",T16<>""),S16-T16,""),"null") -> null | AB16: =LOOKUP($A16,Sheet2!$A$1:$B$233) -> Latin America & Caribbean
A17: Antigua and Barbuda | B17: 2017 | C17: 95.425003 | D17: 24.713001 | E17: 96.739186 | F17: 0 | G17: 3.1663476 | H17: 0.094466114 | I17: null | J17: null | K17: null | L17: null | M17: null | N17: null | O17: null | P17: null | Q17: =IF(A18=A17,B18-B17,"") | R17: =IFERROR(IF($A18=$A17,($E18-$E17)/($B18-$B17),""),"null") | S17: =IFERROR(IF($A18=$A17,($I18-$I17)/($B18-$B17),""),"null") | T17: =IFERROR(IF($A18=$A17,($M18-$M17)/($B18-$B17),""),"null") | U17: =IFERROR(ROUND(E17,0),"null") -> 97 | V17: =IFERROR(ROUND(I17,0),"null") -> null | W17: =IFERROR(ROUND(M17,0),"null") -> null | X17: =IF(AND($A18=$A17,$U17=100,$U18=100),"fullaccesss","") | Y17: =IF(AND($A18=$A17,$V17=100,$V18=100),"fullaccesss","") | Z17: =IF(AND($A18=$A17,$W17=100,$W18=100),"fullaccesss","") | AA17: =IFERROR(IF(AND(S17<>"",T17<>""),S17-T17,""),"null") | AB17: =LOOKUP($A17,Sheet2!$A$1:$B$233) -> Latin America & Caribbean
A18: Argentina | B18: 2015 | C18: 43075.414 | D18: 91.502998 | E18: 98.966588 | F18: 0 | G18: 0.66491438 | H18: 0.36849747 | I18: 92.98366 | J18: 0 | K18: 2.6795449 | L18: 4.3367951 | M18: 99.522163 | N18: 0 | O18: 0.47783695 | P18: 0 | Q18: =IF(A19=A18,B19-B18,"") -> 5 | R18: =IFERROR(IF($A19=$A18,($E19-$E18)/($B19-$B18),""),"null") -> null | S18: =IFERROR(IF($A19=$A18,($I19-$I18)/($B19-$B18),""),"null") -> null | T18: =IFERROR(IF($A19=$A18,($M19-$M18)/($B19-$B18),""),"null") -> 0.05365152 | U18: =IFERROR(ROUND(E18,0),"null") -> 99 | V18: =IFERROR(ROUND(I18,0),"null") -> 93 | W18: =IFERROR(ROUND(M18,0),"null") -> 100 | X18: =IF(AND($A19=$A18,$U18=100,$U19=100),"fullaccesss","") | Y18: =IF(AND($A19=$A18,$V18=100,$V19=100),"fullaccesss","") | Z18: =IF(AND($A19=$A18,$W18=100,$W19=100),"fullaccesss","") -> fullaccesss | AA18: =IFERROR(IF(AND(S18<>"",T18<>""),S18-T18,""),"null") -> null | AB18: =LOOKUP($A18,Sheet2!$A$1:$B$233) -> Latin America & Caribbean
A19: Argentina | B19: 2020 | C19: 45195.777 | D19: 92.111 | E19: null | F19: null | G19: null | H19: null | I19: null | J19: null | K19: null | L19: null | M19: 99.790421 | N19: 0 | O19: 0.20957935 | P19: 0 | Q19: =IF(A20=A19,B20-B19,"") | R19: =IFERROR(IF($A20=$A19,($E20-$E19)/($B20-$B19),""),"null") | S19: =IFERROR(IF($A20=$A19,($I20-$I19)/($B20-$B19),""),"null") | T19: =IFERROR(IF($A20=$A19,($M20-$M19)/($B20-$B19),""),"null") | U19: =IFERROR(ROUND(E19,0),"null") -> null | V19: =IFERROR(ROUND(I19,0),"null") -> null | W19: =IFERROR(ROUND(M19,0),"null") -> 100 | X19: =IF(AND($A20=$A19,$U19=100,$U20=100),"fullaccesss","") | Y19: =IF(AND($A20=$A19,$V19=100,$V20=100),"fullaccesss","") | Z19: =IF(AND($A20=$A19,$W19=100,$W20=100),"fullaccesss","") | AA19: =IFERROR(IF(AND(S19<>"",T19<>""),S19-T19,""),"null") | AB19: =LOOKUP($A19,Sheet2!$A$1:$B$233) -> Latin America & Caribbean
A20: Armenia | B20: 2015 | C20: 2925.5591 | D20: 63.085003 | E20: 99.552567 | F20: 0 | G20: 0.098505084 | H20: 0.34892822 | I20: 99.054779 | J20: 0 | K20: 0 | L20: 0.94522073 | M20: 99.843853 | N20: 0 | O20: 0.1561466 | P20: 0 | Q20: =IF(A21=A20,B21-B20,"") -> 5 | R20: =IFERROR(IF($A21=$A20,($E21-$E20)/($B21-$B20),""),"null") -> 0.083722798 | S20: =IFERROR(IF($A21=$A20,($I21-$I20)/($B21-$B20),""),"null") -> 0.18904415 | T20: =IFERROR(IF($A21=$A20,($M21-$M20)/($B21-$B20),""),"null") -> 0.022125564 | U20: =IFERROR(ROUND(E20,0),"null") -> 100 | V20: =IFERROR(ROUND(I20,0),"null") -> 99 | W20: =IFERROR(ROUND(M20,0),"null") -> 100 | X20: =IF(AND($A21=$A20,$U20=100,$U21=100),"fullaccesss","") -> fullaccesss | Y20: =IF(AND($A21=$A20,$V20=100,$V21=100),"fullaccesss","") | Z20: =IF(AND($A21=$A20,$W20=100,$W21=100),"fullaccesss","") -> fullaccesss | AA20: =IFERROR(IF(AND(S20<>"",T20<>""),S20-T20,""),"null") -> 0.16691858 | AB20: =LOOKUP($A20,Sheet2!$A$1:$B$233) -> Europe & Central Asia
A21: Armenia | B21: 2020 | C21: 2963.2339 | D21: 63.313 | E21: 99.971181 | F21: 0 | G21: 0.028819308 | H21: 0 | I21: 100 | J21: 0 | K21: 0 | L21: 0 | M21: 99.954481 | N21: 0 | O21: 0.045518784 | P21: 0 | Q21: =IF(A22=A21,B22-B21,"") | R21: =IFERROR(IF($A22=$A21,($E22-$E21)/($B22-$B21),""),"null") | S21: =IFERROR(IF($A22=$A21,($I22-$I21)/($B22-$B21),""),"null") | T21: =IFERROR(IF($A22=$A21,($M22-$M21)/($B22-$B21),""),"null") | U21: =IFERROR(ROUND(E21,0),"null") -> 100 | V21: =IFERROR(ROUND(I21,0),"null") -> 100 | W21: =IFERROR(ROUND(M21,0),"null") -> 100 | X21: =IF(AND($A22=$A21,$U21=100,$U22=100),"fullaccesss","") | Y21: =IF(AND($A22=$A21,$V21=100,$V22=100),"fullaccesss","") | Z21: =IF(AND($A22=$A21,$W21=100,$W22=100),"fullaccesss","") | AA21: =IFERROR(IF(AND(S21<>"",T21<>""),S21-T21,""),"null") | AB21: =LOOKUP($A21,Sheet2!$A$1:$B$233) -> Europe & Central Asia
A22: Aruba | B22: 2015 | C22: 104.339 | D22: 43.108002 | E22: 97.869023 | F22: 0 | G22: 1.9599362 | H22: 0.17104041 | I22: null | J22: null | K22: null | L22: null | M22: null | N22: null | O22: null | P22: null | Q22: =IF(A23=A22,B23-B22,"") -> 1 | R22: =IFERROR(IF($A23=$A22,($E23-$E22)/($B23-$B22),""),"null") -> 0 | S22: =IFERROR(IF($A23=$A22,($I23-$I22)/($B23-$B22),""),"null") -> null | T22: =IFERROR(IF($A23=$A22,($M23-$M22)/($B23-$B22),""),"null") -> null | U22: =IFERROR(ROUND(E22,0),"null") -> 98 | V22: =IFERROR(ROUND(I22,0),"null") -> null | W22: =IFERROR(ROUND(M22,0),"null") -> null | X22: =IF(AND($A23=$A22,$U22=100,$U23=100),"fullaccesss","") | Y22: =IF(AND($A23=$A22,$V22=100,$V23=100),"fullaccesss","") | Z22: =IF(AND($A23=$A22,$W22=100,$W23=100),"fullaccesss","") | AA22: =IFERROR(IF(AND(S22<>"",T22<>""),S22-T22,""),"null") -> null | AB22: =LOOKUP($A22,Sheet2!$A$1:$B$233) -> Latin America & Caribbean
A23: Aruba | B23: 2016 | C23: 104.865 | D23: 43.191998 | E23: 97.869023 | F23: 0 | G23: 1.9599362 | H23: 0.17104041 | I23: null | J23: null | K23: null | L23: null | M23: null | N23: null | O23: null | P23: null | Q23: =IF(A24=A23,B24-B23,"") | R23: =IFERROR(IF($A24=$A23,($E24-$E23)/($B24-$B23),""),"null") | S23: =IFERROR(IF($A24=$A23,($I24-$I23)/($B24-$B23),""),"null") | T23: =IFERROR(IF($A24=$A23,($M24-$M23)/($B24-$B23),""),"null") | U23: =IFERROR(ROUND(E23,0),"null") -> 98 | V23: =IFERROR(ROUND(I23,0),"null") -> null | W23: =IFERROR(ROUND(M23,0),"null") -> null | X23: =IF(AND($A24=$A23,$U23=100,$U24=100),"fullaccesss","") | Y23: =IF(AND($A24=$A23,$V23=100,$V24=100),"fullaccesss","") | Z23: =IF(AND($A24=$A23,$W23=100,$W24=100),"fullaccesss","") | AA23: =IFERROR(IF(AND(S23<>"",T23<>""),S23-T23,""),"null") | AB23: =LOOKUP($A23,Sheet2!$A$1:$B$233) -> Latin America & Caribbean
A24: Australia | B24: 2015 | C24: 23932.498 | D24: 85.701004 | E24: 99.970006 | F24: 0 | G24: 0.029994331 | H24: 0 | I24: 100 | J24: 0 | K24: 0 | L24: 0 | M24: 99.965 | N24: 0 | O24: 0.035 | P24: 0 | Q24: =IF(A25=A24,B25-B24,"") -> 5 | R24: =IFERROR(IF($A25=$A24,($E25-$E24)/($B25-$B24),""),"null") -> -3.877e-05 | S24: =IFERROR(IF($A25=$A24,($I25-$I24)/($B25-$B24),""),"null") -> 0 | T24: =IFERROR(IF($A25=$A24,($M25-$M24)/($B25-$B24),""),"null") -> 0 | U24: =IFERROR(ROUND(E24,0),"null") -> 100 | V24: =IFERROR(ROUND(I24,0),"null") -> 100 | W24: =IFERROR(ROUND(M24,0),"null") -> 100 | X24: =IF(AND($A25=$A24,$U24=100,$U25=100),"fullaccesss","") -> fullaccesss | Y24: =IF(AND($A25=$A24,$V24=100,$V25=100),"fullaccesss","") -> fullaccesss | Z24: =IF(AND($A25=$A24,$W24=100,$W25=100),"fullaccesss","") -> fullaccesss | AA24: =IFERROR(IF(AND(S24<>"",T24<>""),S24-T24,""),"null") -> 0 | AB24: =LOOKUP($A24,Sheet2!$A$1:$B$233) -> East Asia & Pacific
A25: Australia | B25: 2020 | C25: 25499.881 | D25: 86.240997 | E25: 99.969812 | F25: 0 | G25: 0.030188179 | H25: 0 | I25: 100 | J25: 0 | K25: 0 | L25: 0 | M25: 99.965 | N25: 0 | O25: 0.035 | P25: 0 | Q25: =IF(A26=A25,B26-B25,"") | R25: =IFERROR(IF($A26=$A25,($E26-$E25)/($B26-$B25),""),"null") | S25: =IFERROR(IF($A26=$A25,($I26-$I25)/($B26-$B25),""),"null") | T25: =IFERROR(IF($A26=$A25,($M26-$M25)/($B26-$B25),""),"null") | U25: =IFERROR(ROUND(E25,0),"null") -> 100 | V25: =IFERROR(ROUND(I25,0),"null") -> 100 | W25: =IFERROR(ROUND(M25,0),"null") -> 100 | X25: =IF(AND($A26=$A25,$U25=100,$U26=100),"fullaccesss","") | Y25: =IF(AND($A26=$A25,$V25=100,$V26=100),"fullaccesss","") | Z25: =IF(AND($A26=$A25,$W25=100,$W26=100),"fullaccesss","") | AA25: =IFERROR(IF(AND(S25<>"",T25<>""),S25-T25,""),"null") | AB25: =LOOKUP($A25,Sheet2!$A$1:$B$233) -> East Asia & Pacific
A26: Austria | B26: 2015 | C26: 8678.667 | D26: 57.715 | E26: 100 | F26: 0 | G26: 0 | H26: 0 | I26: 100 | J26: 0 | K26: 0 | L26: 0 | M26: 100 | N26: 0 | O26: 0 | P26: 0 | Q26: =IF(A27=A26,B27-B26,"") -> 5 | R26: =IFERROR(IF($A27=$A26,($E27-$E26)/($B27-$B26),""),"null") -> 0 | S26: =IFERROR(IF($A27=$A26,($I27-$I26)/($B27-$B26),""),"null") -> 0 | T26: =IFERROR(IF($A27=$A26,($M27-$M26)/($B27-$B26),""),"null") -> 0 | U26: =IFERROR(ROUND(E26,0),"null") -> 100 | V26: =IFERROR(ROUND(I26,0),"null") -> 100 | W26: =IFERROR(ROUND(M26,0),"null") -> 100 | X26: =IF(AND($A27=$A26,$U26=100,$U27=100),"fullaccesss","") -> fullaccesss | Y26: =IF(AND($A27=$A26,$V26=100,$V27=100),"fullaccesss","") -> fullaccesss | Z26: =IF(AND($A27=$A26,$W26=100,$W27=100),"fullaccesss","") -> fullaccesss | AA26: =IFERROR(IF(AND(S26<>"",T26<>""),S26-T26,""),"null") -> 0 | AB26: =LOOKUP($A26,Sheet2!$A$1:$B$233) -> Europe & Central Asia
A27: Austria | B27: 2020 | C27: 9006.4004 | D27: 58.748001 | E27: 100 | F27: 0 | G27: 0 | H27: 0 | I27: 100 | J27: 0 | K27: 0 | L27: 0 | M27: 100 | N27: 0 | O27: 0 | P27: 0 | Q27: =IF(A28=A27,B28-B27,"") | R27: =IFERROR(IF($A28=$A27,($E28-$E27)/($B28-$B27),""),"null") | S27: =IFERROR(IF($A28=$A27,($I28-$I27)/($B28-$B27),""),"null") | T27: =IFERROR(IF($A28=$A27,($M28-$M27)/($B28-$B27),""),"null") | U27: =IFERROR(ROUND(E27,0),"null") -> 100 | V27: =IFERROR(ROUND(I27,0),"null") -> 100 | W27: =IFERROR(ROUND(M27,0),"null") -> 100 | X27: =IF(AND($A28=$A27,$U27=100,$U28=100),"fullaccesss","") | Y27: =IF(AND($A28=$A27,$V27=100,$V28=100),"fullaccesss","") | Z27: =IF(AND($A28=$A27,$W27=100,$W28=100),"fullaccesss","") | AA27: =IFERROR(IF(AND(S27<>"",T27<>""),S27-T27,""),"null") | AB27: =LOOKUP($A27,Sheet2!$A$1:$B$233) -> Europe & Central Asia
A28: Azerbaijan | B28: 2015 | C28: 9622.7412 | D28: 54.714001 | E28: 92.420314 | F28: 1.0022424 | G28: 4.3650895 | H28: 2.2123541 | I28: 84.143213 | J28: 2.2131397 | K28: 8.988206 | L28: 4.655441 | M28: 99.271152 | N28: 0 | O28: 0.53860203 | P28: 0.19024593 | Q28: =IF(A29=A28,B29-B28,"") -> 5 | R28: =IFERROR(IF($A29=$A28,($E29-$E28)/($B29-$B28),""),"null") -> 0.72461243 | S28: =IFERROR(IF($A29=$A28,($I29-$I28)/($B29-$B28),""),"null") -> 1.3565169 | T28: =IFERROR(IF($A29=$A28,($M29-$M28)/($B29-$B28),""),"null") -> 0.14576959 | U28: =IFERROR(ROUND(E28,0),"null") -> 92 | V28: =IFERROR(ROUND(I28,0),"null") -> 84 | W28: =IFERROR(ROUND(M28,0),"null") -> 99 | X28: =IF(AND($A29=$A28,$U28=100,$U29=100),"fullaccesss","") | Y28: =IF(AND($A29=$A28,$V28=100,$V29=100),"fullaccesss","") | Z28: =IF(AND($A29=$A28,$W28=100,$W29=100),"fullaccesss","") | AA28: =IFERROR(IF(AND(S28<>"",T28<>""),S28-T28,""),"null") -> 1.2107473 | AB28: =LOOKUP($A28,Sheet2!$A$1:$B$233) -> Europe & Central Asia
A29: Azerbaijan | B29: 2020 | C29: 10139.175 | D29: 56.397003 | E29: 96.043376 | F29: 1.0427812 | G29: 2.9138427 | H29: 0 | I29: 90.925798 | J29: 2.3915357 | K29: 6.6826664 | L29: 0 | M29: 100 | N29: 0 | O29: 0 | P29: 0 | Q29: =IF(A30=A29,B30-B29,"") | R29: =IFERROR(IF($A30=$A29,($E30-$E29)/($B30-$B29),""),"null") | S29: =IFERROR(IF($A30=$A29,($I30-$I29)/($B30-$B29),""),"null") | T29: =IFERROR(IF($A30=$A29,($M30-$M29)/($B30-$B29),""),"null") | U29: =IFERROR(ROUND(E29,0),"null") -> 96 | V29: =IFERROR(ROUND(I29,0),"null") -> 91 | W29: =IFERROR(ROUND(M29,0),"null") -> 100 | X29: =IF(AND($A30=$A29,$U29=100,$U30=100),"fullaccesss","") | Y29: =IF(AND($A30=$A29,$V29=100,$V30=100),"fullaccesss","") | Z29: =IF(AND($A30=$A29,$W29=100,$W30=100),"fullaccesss","") | AA29: =IFERROR(IF(AND(S29<>"",T29<>""),S29-T29,""),"null") | AB29: =LOOKUP($A29,Sheet2!$A$1:$B$233) -> Europe & Central Asia
A30: Bahamas | B30: 2015 | C30: 374.20001 | D30: 82.745995 | E30: 98.886961 | F30: 0 | G30: 1.1130395 | H30: 0 | I30: null | J30: null | K30: null | L30: null | M30: null | N30: null | O30: null | P30: null | Q30: =IF(A31=A30,B31-B30,"") -> 4 | R30: =IFERROR(IF($A31=$A30,($E31-$E30)/($B31-$B30),""),"null") -> 0 | S30: =IFERROR(IF($A31=$A30,($I31-$I30)/($B31-$B30),""),"null") -> null | T30: =IFERROR(IF($A31=$A30,($M31-$M30)/($B31-$B30),""),"null") -> null | U30: =IFERROR(ROUND(E30,0),"null") -> 99 | V30: =IFERROR(ROUND(I30,0),"null") -> null | W30: =IFERROR(ROUND(M30,0),"null") -> null | X30: =IF(AND($A31=$A30,$U30=100,$U31=100),"fullaccesss","") | Y30: =IF(AND($A31=$A30,$V30=100,$V31=100),"fullaccesss","") | Z30: =IF(AND($A31=$A30,$W30=100,$W31=100),"fullaccesss","") | AA30: =IFERROR(IF(AND(S30<>"",T30<>""),S30-T30,""),"null") -> null | AB30: =LOOKUP($A30,Sheet2!$A$1:$B$233) -> Latin America & Caribbean
A31: Bahamas | B31: 2019 | C31: 389.48599 | D31: 83.131996 | E31: 98.886961 | F31: 0 | G31: 1.1130395 | H31: 0 | I31: null | J31: null | K31: null | L31: null | M31: null | N31: null | O31: null | P31: null | Q31: =IF(A32=A31,B32-B31,"") | R31: =IFERROR(IF($A32=$A31,($E32-$E31)/($B32-$B31),""),"null") | S31: =IFERROR(IF($A32=$A31,($I32-$I31)/($B32-$B31),""),"null") | T31: =IFERROR(IF($A32=$A31,($M32-$M31)/($B32-$B31),""),"null") | U31: =IFERROR(ROUND(E31,0),"null") -> 99 | V31: =IFERROR(ROUND(I31,0),"null") -> null | W31: =IFERROR(ROUND(M31,0),"null") -> null | X31: =IF(AND($A32=$A31,$U31=100,$U32=100),"fullaccesss","") | Y31: =IF(AND($A32=$A31,$V31=100,$V32=100),"fullaccesss","") | Z31: =IF(AND($A32=$A31,$W31=100,$W32=100),"fullaccesss","") | AA31: =IFERROR(IF(AND(S31<>"",T31<>""),S31-T31,""),"null") | AB31: =LOOKUP($A31,Sheet2!$A$1:$B$233) -> Latin America & Caribbean
A32: Bahrain | B32: 2015 | C32: 1371.853 | D32: 88.998993 | E32: 100 | F32: 0 | G32: 0 | H32: 0 | I32: null | J32: null | K32: null | L32: null | M32: null | N32: null | O32: null | P32: null | Q32: =IF(A33=A32,B33-B32,"") -> 5 | R32: =IFERROR(IF($A33=$A32,($E33-$E32)/($B33-$B32),""),"null") -> 0 | S32: =IFERROR(IF($A33=$A32,($I33-$I32)/($B33-$B32),""),"null") -> null | T32: =IFERROR(IF($A33=$A32,($M33-$M32)/($B33-$B32),""),"null") -> null | U32: =IFERROR(ROUND(E32,0),"null") -> 100 | V32: =IFERROR(ROUND(I32,0),"null") -> null | W32: =IFERROR(ROUND(M32,0),"null") -> null | X32: =IF(AND($A33=$A32,$U32=100,$U33=100),"fullaccesss","") -> fullaccesss | Y32: =IF(AND($A33=$A32,$V32=100,$V33=100),"fullaccesss","") | Z32: =IF(AND($A33=$A32,$W32=100,$W33=100),"fullaccesss","") | AA32: =IFERROR(IF(AND(S32<>"",T32<>""),S32-T32,""),"null") -> null | AB32: =LOOKUP($A32,Sheet2!$A$1:$B$233) -> Europe & Central Asia
A33: Bahrain | B33: 2020 | C33: 1701.583 | D33: 89.506004 | E33: 100 | F33: 0 | G33: 0 | H33: 0 | I33: null | J33: null | K33: null | L33: null | M33: null | N33: null | O33: null | P33: null | Q33: =IF(A34=A33,B34-B33,"") | R33: =IFERROR(IF($A34=$A33,($E34-$E33)/($B34-$B33),""),"null") | S33: =IFERROR(IF($A34=$A33,($I34-$I33)/($B34-$B33),""),"null") | T33: =IFERROR(IF($A34=$A33,($M34-$M33)/($B34-$B33),""),"null") | U33: =IFERROR(ROUND(E33,0),"null") -> 100 | V33: =IFERROR(ROUND(I33,0),"null") -> null | W33: =IFERROR(ROUND(M33,0),"null") -> null | X33: =IF(AND($A34=$A33,$U33=100,$U34=100),"fullaccesss","") | Y33: =IF(AND($A34=$A33,$V33=100,$V34=100),"fullaccesss","") | Z33: =IF(AND($A34=$A33,$W33=100,$W34=100),"fullaccesss","") | AA33: =IFERROR(IF(AND(S33<>"",T33<>""),S33-T33,""),"null") | AB33: =LOOKUP($A33,Sheet2!$A$1:$B$233) -> Europe & Central Asia
A34: Bangladesh | B34: 2015 | C34: 156256.28 | D34: 34.308002 | E34: 97.101602 | F34: 1.087989 | G34: 0.72156166 | H34: 1.0888469 | I34: 96.773011 | J34: 1.0462142 | K34: 0.73174732 | L34: 1.4490272 | M34: 97.73078 | N34: 1.1679782 | O34: 0.70205843 | P34: 0.39918371 | Q34: =IF(A35=A34,B35-B34,"") -> 5 | R34: =IFERROR(IF($A35=$A34,($E35-$E34)/($B35-$B34),""),"null") -> 0.11927156 | S34: =IFERROR(IF($A35=$A34,($I35-$I34)/($B35-$B34),""),"null") -> 0.2214453 | T34: =IFERROR(IF($A35=$A34,($M35-$M34)/($B35-$B34),""),"null") -> -0.065600342 | U34: =IFERROR(ROUND(E34,0),"null") -> 97 | V34: =IFERROR(ROUND(I34,0),"null") -> 97 | W34: =IFERROR(ROUND(M34,0),"null") -> 98 | X34: =IF(AND($A35=$A34,$U34=100,$U35=100),"fullaccesss","") | Y34: =IF(AND($A35=$A34,$V34=100,$V35=100),"fullaccesss","") | Z34: =IF(AND($A35=$A34,$W34=100,$W35=100),"fullaccesss","") | AA34: =IFERROR(IF(AND(S34<>"",T34<>""),S34-T34,""),"null") -> 0.28704564 | AB34: =LOOKUP($A34,Sheet2!$A$1:$B$233) -> South Asia
A35: Bangladesh | B35: 2020 | C35: 164689.39 | D35: 38.177002 | E35: 97.69796 | F35: 1.1564259 | G35: 0.4626557 | H35: 0.68295817 | I35: 97.880238 | J35: 0.85810498 | K35: 0.31648024 | L35: 0.94517702 | M35: 97.402778 | N35: 1.6395201 | O35: 0.69937521 | P35: 0.25832669 | Q35: =IF(A36=A35,B36-B35,"") | R35: =IFERROR(IF($A36=$A35,($E36-$E35)/($B36-$B35),""),"null") | S35: =IFERROR(IF($A36=$A35,($I36-$I35)/($B36-$B35),""),"null") | T35: =IFERROR(IF($A36=$A35,($M36-$M35)/($B36-$B35),""),"null") | U35: =IFERROR(ROUND(E35,0),"null") -> 98 | V35: =IFERROR(ROUND(I35,0),"null") -> 98 | W35: =IFERROR(ROUND(M35,0),"null") -> 97 | X35: =IF(AND($A36=$A35,$U35=100,$U36=100),"fullaccesss","") | Y35: =IF(AND($A36=$A35,$V35=100,$V36=100),"fullaccesss","") | Z35: =IF(AND($A36=$A35,$W35=100,$W36=100),"fullaccesss","") | AA35: =IFERROR(IF(AND(S35<>"",T35<>""),S35-T35,""),"null") | AB35: =LOOKUP($A35,Sheet2!$A$1:$B$233) -> South Asia
A36: Barbados | B36: 2015 | C36: 285.327 | D36: 31.248999 | E36: 98.474445 | F36: 0.26749191 | G36: 1.2580634 | H36: 0 | I36: null | J36: null | K36: null | L36: null | M36: null | N36: null | O36: null | P36: null | Q36: =IF(A37=A36,B37-B36,"") -> 5 | R36: =IFERROR(IF($A37=$A36,($E37-$E36)/($B37-$B36),""),"null") -> 0.008001136 | S36: =IFERROR(IF($A37=$A36,($I37-$I36)/($B37-$B36),""),"null") -> null | T36: =IFERROR(IF($A37=$A36,($M37-$M36)/($B37-$B36),""),"null") -> null | U36: =IFERROR(ROUND(E36,0),"null") -> 98 | V36: =IFERROR(ROUND(I36,0),"null") -> null | W36: =IFERROR(ROUND(M36,0),"null") -> null | X36: =IF(AND($A37=$A36,$U36=100,$U37=100),"fullaccesss","") | Y36: =IF(AND($A37=$A36,$V36=100,$V37=100),"fullaccesss","") | Z36: =IF(AND($A37=$A36,$W36=100,$W37=100),"fullaccesss","") | AA36: =IFERROR(IF(AND(S36<>"",T36<>""),S36-T36,""),"null") -> null | AB36: =LOOKUP($A36,Sheet2!$A$1:$B$233) -> Latin America & Caribbean
A37: Barbados | B37: 2020 | C37: 287.371 | D37: 31.191 | E37: 98.51445 | F37: 0.26760058 | G37: 1.217949 | H37: 0 | I37: null | J37: null | K37: null | L37: null | M37: null | N37: null | O37: null | P37: null | Q37: =IF(A38=A37,B38-B37,"") | R37: =IFERROR(IF($A38=$A37,($E38-$E37)/($B38-$B37),""),"null") | S37: =IFERROR(IF($A38=$A37,($I38-$I37)/($B38-$B37),""),"null") | T37: =IFERROR(IF($A38=$A37,($M38-$M37)/($B38-$B37),""),"null") | U37: =IFERROR(ROUND(E37,0),"null") -> 99 | V37: =IFERROR(ROUND(I37,0),"null") -> null | W37: =IFERROR(ROUND(M37,0),"null") -> null | X37: =IF(AND($A38=$A37,$U37=100,$U38=100),"fullaccesss","") | Y37: =IF(AND($A38=$A37,$V37=100,$V38=100),"fullaccesss","") | Z37: =IF(AND($A38=$A37,$W37=100,$W38=100),"fullaccesss","") | AA37: =IFERROR(IF(AND(S37<>"",T37<>""),S37-T37,""),"null") | AB37: =LOOKUP($A37,Sheet2!$A$1:$B$233) -> Latin America & Caribbean
A38: Belarus | B38: 2015 | C38: 9439.4238 | D38: 77.181 | E38: 96.477067 | F38: 3.3001301 | G38: 0.2228028 | H38: 0 | I38: 98.330672 | J38: 0.99323911 | K38: 0.67608929 | L38: 0 | M38: 95.929035 | N38: 3.9821754 | O38: 0.088789424 | P38: 0 | Q38: =IF(A39=A38,B39-B38,"") -> 5 | R38: =IFERROR(IF($A39=$A38,($E39-$E38)/($B39-$B38),""),"null") -> 0.011531798 | S38: =IFERROR(IF($A39=$A38,($I39-$I38)/($B39-$B38),""),"null") -> 0.046690142 | T38: =IFERROR(IF($A39=$A38,($M39-$M38)/($B39-$B38),""),"null") -> 0.016367688 | U38: =IFERROR(ROUND(E38,0),"null") -> 96 | V38: =IFERROR(ROUND(I38,0),"null") -> 98 | W38: =IFERROR(ROUND(M38,0),"null") -> 96 | X38: =IF(AND($A39=$A38,$U38=100,$U39=100),"fullaccesss","") | Y38: =IF(AND($A39=$A38,$V38=100,$V39=100),"fullaccesss","") | Z38: =IF(AND($A39=$A38,$W38=100,$W39=100),"fullaccesss","") | AA38: =IFERROR(IF(AND(S38<>"",T38<>""),S38-T38,""),"null") -> 0.030322454 | AB38: =LOOKUP($A38,Sheet2!$A$1:$B$233) -> Europe & Central Asia
A39: Belarus | B39: 2020 | C39: 9449.3213 | D39: 79.483002 | E39: 96.534726 | F39: 3.3721195 | G39: 0.093154368 | H39: 0 | I39: 98.564122 | J39: 0.9955972 | K39: 0.44028049 | L39: 0 | M39: 96.010874 | N39: 3.9855726 | O39: 0.003553732 | P39: 0 | Q39: =IF(A40=A39,B40-B39,"") | R39: =IFERROR(IF($A40=$A39,($E40-$E39)/($B40-$B39),""),"null") | S39: =IFERROR(IF($A40=$A39,($I40-$I39)/($B40-$B39),""),"null") | T39: =IFERROR(IF($A40=$A39,($M40-$M39)/($B40-$B39),""),"null") | U39: =IFERROR(ROUND(E39,0),"null") -> 97 | V39: =IFERROR(ROUND(I39,0),"null") -> 99 | W39: =IFERROR(ROUND(M39,0),"null") -> 96 | X39: =IF(AND($A40=$A39,$U39=100,$U40=100),"fullaccesss","") | Y39: =IF(AND($A40=$A39,$V39=100,$V40=100),"fullaccesss","") | Z39: =IF(AND($A40=$A39,$W39=100,$W40=100),"fullaccesss","") | AA39: =IFERROR(IF(AND(S39<>"",T39<>""),S39-T39,""),"null") | AB39: =LOOKUP($A39,Sheet2!$A$1:$B$233) -> Europe & Central Asia
A40: Belgium | B40: 2015 | C40: 11287.931 | D40: 97.875999 | E40: 99.999998 | F40: 0 | G40: 2.2980245e-06 | H40: 0 | I40: 100 | J40: 0 | K40: 0 | L40: 0 | M40: 100 | N40: 0 | O40: 0 | P40: 0 | Q40: =IF(A41=A40,B41-B40,"") -> 5 | R40: =IFERROR(IF($A41=$A40,($E41-$E40)/($B41-$B40),""),"null") -> -2.5e-07 | S40: =IFERROR(IF($A41=$A40,($I41-$I40)/($B41-$B40),""),"null") -> 0 | T40: =IFERROR(IF($A41=$A40,($M41-$M40)/($B41-$B40),""),"null") -> 0 | U40: =IFERROR(ROUND(E40,0),"null") -> 100 | V40: =IFERROR(ROUND(I40,0),"null") -> 100 | W40: =IFERROR(ROUND(M40,0),"null") -> 100 | X40: =IF(AND($A41=$A40,$U40=100,$U41=100),"fullaccesss","") -> fullaccesss | Y40: =IF(AND($A41=$A40,$V40=100,$V41=100),"fullaccesss","") -> fullaccesss | Z40: =IF(AND($A41=$A40,$W40=100,$W41=100),"fullaccesss","") -> fullaccesss | AA40: =IFERROR(IF(AND(S40<>"",T40<>""),S40-T40,""),"null") -> 0 | AB40: =LOOKUP($A40,Sheet2!$A$1:$B$233) -> Europe & Central Asia
...

Sheet Pivot Table 3
A2: Region | B2: AVERAGE of ARC_n | C2: AVERAGE of ARC_r | D2: AVERAGE of ARC_u
A3: East Asia & Pacific | B3: 0.2784349 | C3: 0.5077948 | D3: 0.23295792
A4: Europe & Central Asia | B4: 0.11168578 | C4: 0.22440971 | D4: 0.046995216
A5: Latin America & Caribbean | B5: 0.14442485 | C5: 0.6803145 | D5: 0.071521594
A6: Middle East & North Africa | B6: 0.34556302 | C6: 0.73698723 | D6: 0.12397804
A7: North America | B7: 0.017158396 | C7: 0.14233131 | D7: 0.0020331735
A8: South Asia | B8: 0.25322079 | C8: 0.34827083 | D8: 0.025216355
A9: Sub-Saharan Africa | B9: 0.55828082 | C9: 0.60421592 | D9: 0.27036667
A10: #N/A | B10: 2.7503265 | C10: 2.6678826 | D10: 2.6682119
A11: Grand Total | B11: 0.27674414 | C11: 0.4844937 | D11: 0.1548234

Sheet Summary sheet
B1: Average | C1: Minimum | D1: Maximum
A2: y_diff | B2: =ROUND(AVERAGE('Estimates of the use of water ('!$Q$2:$Q$463),2) -> 4.8 | C2: =MIN('Estimates of the use of water ('!$Q$2:$Q$463) -> 1 | D2: =MAX('Estimates of the use of water ('!$Q$2:$Q$463) -> 5
A3: ARC_n | B3: =AVERAGE('Estimates of the use of water ('!$R$2:$R$463) -> 0.27674414 | C3: =MIN('Estimates of the use of water ('!$R$2:$R$463) -> -1.0217887 | D3: =MAX('Estimates of the use of water ('!$R$2:$R$463) -> 2.7503265
A4: ARC_r | B4: =AVERAGE('Estimates of the use of water ('!$S$2:$S$463) -> 0.4844937 | C4: =MIN('Estimates of the use of water ('!$S$2:$S$463) -> -1.227381 | D4: =MAX('Estimates of the use of water ('!$S$2:$S$463) -> 2.6678826
A5: ARC_u | B5: =AVERAGE('Estimates of the use of water ('!$T$2:$T$463) -> 0.1548234 | C5: =MIN('Estimates of the use of water ('!$T$2:$T$463) -> -1.6200868 | D5: =MAX('Estimates of the use of water ('!$T$2:$T$463) -> 2.6682119
B6: count
A7: Number of countries that have missing ARc_n value (null) | B7: 2
A8: Number of countries that have missing ARC_r value (null) | B8: 64
A9: Number of countries that have missing ARc_u value (null) | B9: 50
B10: count
A11: ARC_n_full | B11: =COUNTIF('Estimates of the use of water ('!X$2:X$463,"fullaccesss") -> 62
A12: ARC_r_full | B12: =COUNTIF('Estimates of the use of water ('!Y$2:Y$463,"fullaccesss") -> 29
A13: ARC_u_full | B13: =COUNTIF('Estimates of the use of water ('!Z$2:Z$463,"fullaccesss") -> 55
B14: count
A15: ARC_n=0 and doesn't have full access | B15: =COUNTIFS('Estimates of the use of water ('!R2:R463,"=0",'Estimates of the use of water ('!X2:X463, "<>fullaccesss") -> 16
A16: ARC_r=o and doesn't have full access | B16: =COUNTIFS('Estimates of the use of water ('!S2:S463,"=0",'Estimates of the use of water ('!Y2:Y463, "<>fullaccesss") -> 5
A17: ARC_u=o and doesn't have full access | B17: =COUNTIFS('Estimates of the use of water ('!T2:T463,"=0",'Estimates of the use of water ('!Z2:Z463, "<>fullaccesss") -> 7
B18: count
A19: ARC_n<0 and doesn't have full access | B19: =COUNTIFS('Estimates of the use of water ('!R2:R463,"<0",'Estimates of the use of water ('!X2:X463, "<>fullaccesss") -> 16
A20: ARC_r<o and doesn't have full access | B20: =COUNTIFS('Estimates of the use of water ('!S2:S463,"<0",'Estimates of the use of water ('!Y2:Y463, "<>fullaccesss") -> 17
A21: ARC_u<o and doesn't have full access | B21: =COUNTIFS('Estimates of the use of water ('!T2:T463,"<0",'Estimates of the use of water ('!Z2:Z463, "<>fullaccesss") -> 26
B22: count
A23: ARC_n>0 and doesn't have full access | B23: =COUNTIFS('Estimates of the use of water ('!R2:R463,">0",'Estimates of the use of water ('!X2:X463, "<>fullaccesss") -> 135
A24: ARC_r>o and doesn't have full access | B24: =COUNTIFS('Estimates of the use of water ('!S2:S463,">0",'Estimates of the use of water ('!Y2:Y463, "<>fullaccesss") -> 116
A25: ARC_u>o and doesn't have full access | B25: =COUNTIFS('Estimates of the use of water ('!T2:T463,">0",'Estimates of the use of water ('!Z2:Z463, "<>fullaccesss") -> 93

Sheet Sheet2
A1: name | B1: region
A2: Afghanistan | B2: South Asia
A3: Albania | B3: Europe & Central Asia
A4: Algeria | B4: Middle East & North Africa
A5: American Samoa | B5: East Asia & Pacific
A6: Andorra | B6: Europe & Central Asia
A7: Angola | B7: Sub-Saharan Africa
A8: Anguilla | B8: Latin America & Caribbean
A9: Antigua and Barbuda | B9: Latin America & Caribbean
A10: Argentina | B10: Latin America & Caribbean
A11: Armenia | B11: Europe & Central Asia
A12: Aruba | B12: Latin America & Caribbean
... A233: Zimbabwe | B233: Sub-Saharan Africa

Sheet Copy of Estimates of the use of
A1: name | B1: year | C1: pop_n | D1: pop_u | E1: wat_bas_n | F1: wat_lim_n | G1: wat_unimp_n | H1: wat_sur_n | I1: wat_bas_r | J1: wat_lim_r | K1: wat_unimp_r | L1: wat_sur_r | M1: wat_bas_u | N1: wat_lim_u | O1: wat_unimp_u | P1: wat_sur_u | Q1: y_diff | R1: ARC_n | S1: ARC_r | T1: ARC_u | U1: wat_bas_n(rounded) | V1: wat_bas_r(rounded) | W1: wat_bas_u(rounded) | X1: ARC_n_full | Y1: ARC_r_full | Z1: ARC_u_full | AA1: ARC_diff
A2: Afghanistan | B2: 2015 | C2: 34413.602 | D2: 24.802999 | E2: 61.339781 | F2: 3.5111995 | G2: 22.168784 | H2: 12.980236 | I2: 52.988502 | J2: 3.8611366 | K2: 26.553268 | L2: 16.597094 | M2: 86.658941 | N2: 2.4502706 | O2: 8.8760357 | P2: 2.014753 | Q2: =IF(A3=A2,B3-B2,"") -> 5 | R2: =IFERROR(IF($A3=$A2,($E3-$E2)/($B3-$B2),""),"null") -> 2.7503265 | S2: =IFERROR(IF($A3=$A2,($I3-$I2)/($B3-$B2),""),"null") -> 2.6678826 | T2: =IFERROR(IF($A3=$A2,($M3-$M2)/($B3-$B2),""),"null") -> 2.6682119 | U2: =IFERROR(ROUND(E2,0),"null") -> 61 | V2: =IFERROR(ROUND(I2,0),"null") -> 53 | W2: =IFERROR(ROUND(M2,0),"null") -> 87 | X2: =IF(AND($A3=$A2,$U2=100,$U3=100),"fullaccesss","") | Y2: =IF(AND($A3=$A2,$V2=100,$V3=100),"fullaccesss","") | Z2: =IF(AND($A3=$A2,$W2=100,$W3=100),"fullaccesss","") | AA2: =IFERROR(IF(AND(S2<>"",T2<>""),S2-T2,""),"null") -> -0.000329218
A3: Afghanistan | B3: 2020 | C3: 38928.34 | D3: 26.025999 | E3: 75.091413 | F3: 1.4475417 | G3: 14.560263 | H3: 8.9007822 | I3: 66.327915 | J3: 1.9568249 | K3: 19.682949 | L3: 12.032311 | M3: 100 | N3: 0 | O3: 0 | P3: 0 | Q3: =IF(A4=A3,B4-B3,"") | R3: =IFERROR(IF($A4=$A3,($E4-$E3)/($B4-$B3),""),"null") | S3: =IFERROR(IF($A4=$A3,($I4-$I3)/($B4-$B3),""),"null") | T3: =IFERROR(IF($A4=$A3,($M4-$M3)/($B4-$B3),""),"null") | U3: =IFERROR(ROUND(E3,0),"null") -> 75 | V3: =IFERROR(ROUND(I3,0),"null") -> 66 | W3: =IFERROR(ROUND(M3,0),"null") -> 100 | X3: =IF(AND($A4=$A3,$U3=100,$U4=100),"fullaccesss","") | Y3: =IF(AND($A4=$A3,$V3=100,$V4=100),"fullaccesss","") | Z3: =IF(AND($A4=$A3,$W3=100,$W4=100),"fullaccesss","") | AA3: =IFERROR(IF(AND(S3<>"",T3<>""),S3-T3,""),"null")
A4: Albania | B4: 2015 | C4: 2890.5239 | D4: 57.433998 | E4: 93.394325 | F4: 3.6263837 | G4: 2.979291 | H4: 0 | I4: 90.627275 | J4: 5.2631726 | K4: 4.1095527 | L4: 0 | M4: 95.445067 | N4: 2.4133118 | O4: 2.1416212 | P4: 0 | Q4: =IF(A5=A4,B5-B4,"") -> 5 | R4: =IFERROR(IF($A5=$A4,($E5-$E4)/($B5-$B4),""),"null") -> 0.3347427 | S4: =IFERROR(IF($A5=$A4,($I5-$I4)/($B5-$B4),""),"null") -> 0.69281669 | T4: =IFERROR(IF($A5=$A4,($M5-$M4)/($B5-$B4),""),"null") -> 0.043748432 | U4: =IFERROR(ROUND(E4,0),"null") -> 93 | V4: =IFERROR(ROUND(I4,0),"null") -> 91 | W4: =IFERROR(ROUND(M4,0),"null") -> 95 | X4: =IF(AND($A5=$A4,$U4=100,$U5=100),"fullaccesss","") | Y4: =IF(AND($A5=$A4,$V4=100,$V5=100),"fullaccesss","") | Z4: =IF(AND($A5=$A4,$W4=100,$W5=100),"fullaccesss","") | AA4: =IFERROR(IF(AND(S4<>"",T4<>""),S4-T4,""),"null") -> 0.64906826
A5: Albania | B5: 2020 | C5: 2877.8 | D5: 62.112 | E5: 95.068039 | F5: 1.8846561 | G5: 3.0473051 | H5: 0 | I5: 94.091358 | J5: 2.305265 | K5: 3.603377 | L5: 0 | M5: 95.663809 | N5: 1.6280868 | O5: 2.7081041 | P5: 0 | Q5: =IF(A6=A5,B6-B5,"") | R5: =IFERROR(IF($A6=$A5,($E6-$E5)/($B6-$B5),""),"null") | S5: =IFERROR(IF($A6=$A5,($I6-$I5)/($B6-$B5),""),"null") | T5: =IFERROR(IF($A6=$A5,($M6-$M5)/($B6-$B5),""),"null") | U5: =IFERROR(ROUND(E5,0),"null") -> 95 | V5: =IFERROR(ROUND(I5,0),"null") -> 94 | W5: =IFERROR(ROUND(M5,0),"null") -> 96 | X5: =IF(AND($A6=$A5,$U5=100,$U6=100),"fullaccesss","") | Y5: =IF(AND($A6=$A5,$V5=100,$V6=100),"fullaccesss","") | Z5: =IF(AND($A6=$A5,$W5=100,$W6=100),"fullaccesss","") | AA5: =IFERROR(IF(AND(S5<>"",T5<>""),S5-T5,""),"null")
A6: Algeria | B6: 2015 | C6: 39728.02 | D6: 70.848 | E6: 93.409562 | F6: 5.1577809 | G6: 1.2754647 | H6: 0.15719289 | I6: 88.352707 | J6: 8.6857531 | K6: 2.5804318 | L6: 0.38110822 | M6: 95.490315 | N6: 3.7061173 | O6: 0.73851009 | P6: 0.065057898 | Q6: =IF(A7=A6,B7-B6,"") -> 5 | R6: =IFERROR(IF($A7=$A6,($E7-$E6)/($B7-$B6),""),"null") -> 0.20555369 | S6: =IFERROR(IF($A7=$A6,($I7-$I6)/($B7-$B6),""),"null") -> 0.33696621 | T6: =IFERROR(IF($A7=$A6,($M7-$M6)/($B7-$B6),""),"null") -> 0.10288423 | U6: =IFERROR(ROUND(E6,0),"null") -> 93 | V6: =IFERROR(ROUND(I6,0),"null") -> 88 | W6: =IFERROR(ROUND(M6,0),"null") -> 95 | X6: =IF(AND($A7=$A6,$U6=100,$U7=100),"fullaccesss","") | Y6: =IF(AND($A7=$A6,$V6=100,$V7=100),"fullaccesss","") | Z6: =IF(AND($A7=$A6,$W6=100,$W7=100),"fullaccesss","") | AA6: =IFERROR(IF(AND(S6<>"",T6<>""),S6-T6,""),"null") -> 0.23408198
A7: Algeria | B7: 2020 | C7: 43851.043 | D7: 73.733002 | E7: 94.43733 | F7: 4.9858808 | G7: 0.53183666 | H7: 0.044952533 | I7: 90.037538 | J7: 8.7967221 | K7: 0.99460303 | L7: 0.17113693 | M7: 96.004736 | N7: 3.6282886 | O7: 0.36697555 | P7: 0 | Q7: =IF(A8=A7,B8-B7,"") | R7: =IFERROR(IF($A8=$A7,($E8-$E7)/($B8-$B7),""),"null") | S7: =IFERROR(IF($A8=$A7,($I8-$I7)/($B8-$B7),""),"null") | T7: =IFERROR(IF($A8=$A7,($M8-$M7)/($B8-$B7),""),"null") | U7: =IFERROR(ROUND(E7,0),"null") -> 94 | V7: =IFERROR(ROUND(I7,0),"null") -> 90 | W7: =IFERROR(ROUND(M7,0),"null") -> 96 | X7: =IF(AND($A8=$A7,$U7=100,$U8=100),"fullaccesss","") | Y7: =IF(AND($A8=$A7,$V7=100,$V8=100),"fullaccesss","") | Z7: =IF(AND($A8=$A7,$W7=100,$W8=100),"fullaccesss","") | AA7: =IFERROR(IF(AND(S7<>"",T7<>""),S7-T7,""),"null")
A8: American Samoa | B8: 2015 | C8: 55.806 | D8: 87.238007 | E8: 99.619103 | F8: 0 | G8: 0.38089685 | H8: 0 | I8: null | J8: null | K8: null | L8: null | M8: null | N8: null | O8: null | P8: null | Q8: =IF(A9=A8,B9-B8,"") -> 5 | R8: =IFERROR(IF($A9=$A8,($E9-$E8)/($B9-$B8),""),"null") -> 0.030933702 | S8: =IFERROR(IF($A9=$A8,($I9-$I8)/($B9-$B8),""),"null") -> null | T8: =IFERROR(IF($A9=$A8,($M9-$M8)/($B9-$B8),""),"null") -> null | U8: =IFERROR(ROUND(E8,0),"null") -> 100 | V8: =IFERROR(ROUND(I8,0),"null") -> null | W8: =IFERROR(ROUND(M8,0),"null") -> null | X8: =IF(AND($A9=$A8,$U8=100,$U9=100),"fullaccesss","") -> fullaccesss | Y8: =IF(AND($A9=$A8,$V8=100,$V9=100),"fullaccesss","") | Z8: =IF(AND($A9=$A8,$W8=100,$W9=100),"fullaccesss","") | AA8: =IFERROR(IF(AND(S8<>"",T8<>""),S8-T8,""),"null") -> null
A9: American Samoa | B9: 2020 | C9: 55.196999 | D9: 87.153 | E9: 99.773772 | F9: 0 | G9: 0.22622834 | H9: 0 | I9: null | J9: null | K9: null | L9: null | M9: null | N9: null | O9: null | P9: null | Q9: =IF(A10=A9,B10-B9,"") | R9: =IFERROR(IF($A10=$A9,($E10-$E9)/($B10-$B9),""),"null") | S9: =IFERROR(IF($A10=$A9,($I10-$I9)/($B10-$B9),""),"null") | T9: =IFERROR(IF($A10=$A9,($M10-$M9)/($B10-$B9),""),"null") | U9: =IFERROR(ROUND(E9,0),"null") -> 100 | V9: =IFERROR(ROUND(I9,0),"null") -> null | W9: =IFERROR(ROUND(M9,0),"null") -> null | X9: =IF(AND($A10=$A9,$U9=100,$U10=100),"fullaccesss","") | Y9: =IF(AND($A10=$A9,$V9=100,$V10=100),"fullaccesss","") | Z9: =IF(AND($A10=$A9,$W9=100,$W10=100),"fullaccesss","") | AA9: =IFERROR(IF(AND(S9<>"",T9<>""),S9-T9,""),"null")
A10: Andorra | B10: 2015 | C10: 77.992996 | D10: 88.344994 | E10: 99.999998 | F10: 0 | G10: 2.4455384e-06 | H10: 0 | I10: 100 | J10: 0 | K10: 0 | L10: 0 | M10: 100 | N10: 0 | O10: 0 | P10: 0 | Q10: =IF(A11=A10,B11-B10,"") -> 5 | R10: =IFERROR(IF($A11=$A10,($E11-$E10)/($B11-$B10),""),"null") -> 1.23e-06 | S10: =IFERROR(IF($A11=$A10,($I11-$I10)/($B11-$B10),""),"null") -> 0 | T10: =IFERROR(IF($A11=$A10,($M11-$M10)/($B11-$B10),""),"null") -> 0 | U10: =IFERROR(ROUND(E10,0),"null") -> 100 | V10: =IFERROR(ROUND(I10,0),"null") -> 100 | W10: =IFERROR(ROUND(M10,0),"null") -> 100 | X10: =IF(AND($A11=$A10,$U10=100,$U11=100),"fullaccesss","") -> fullaccesss | Y10: =IF(AND($A11=$A10,$V10=100,$V11=100),"fullaccesss","") -> fullaccesss | Z10: =IF(AND($A11=$A10,$W10=100,$W11=100),"fullaccesss","") -> fullaccesss | AA10: =IFERROR(IF(AND(S10<>"",T10<>""),S10-T10,""),"null") -> 0
A11: Andorra | B11: 2020 | C11: 77.264999 | D11: 87.916 | E11: 100 | F11: 0 | G11: 0 | H11: 0 | I11: 100 | J11: 0 | K11: 0 | L11: 0 | M11: 100 | N11: 0 | O11: 0 | P11: 0 | Q11: =IF(A12=A11,B12-B11,"") | R11: =IFERROR(IF($A12=$A11,($E12-$E11)/($B12-$B11),""),"null") | S11: =IFERROR(IF($A12=$A11,($I12-$I11)/($B12-$B11),""),"null") | T11: =IFERROR(IF($A12=$A11,($M12-$M11)/($B12-$B11),""),"null") | U11: =IFERROR(ROUND(E11,0),"null") -> 100 | V11: =IFERROR(ROUND(I11,0),"null") -> 100 | W11: =IFERROR(ROUND(M11,0),"null") -> 100 | X11: =IF(AND($A12=$A11,$U11=100,$U12=100),"fullaccesss","") | Y11: =IF(AND($A12=$A11,$V11=100,$V12=100),"fullaccesss","") | Z11: =IF(AND($A12=$A11,$W11=100,$W12=100),"fullaccesss","") | AA11: =IFERROR(IF(AND(S11<>"",T11<>""),S11-T11,""),"null")
A12: Angola | B12: 2015 | C12: 27884.381 | D12: 63.445995 | E12: 54.316928 | F12: 11.368619 | G12: 17.372356 | H12: 16.942097 | I12: 26.714369 | J12: 9.9310693 | K12: 21.725308 | L12: 41.629254 | M12: 70.219965 | N12: 12.196853 | O12: 14.864431 | P12: 2.7187499 | Q12: =IF(A13=A12,B13-B12,"") -> 5 | R12: =IFERROR(IF($A13=$A12,($E13-$E12)/($B13-$B12),""),"null") -> 0.57016185 | S12: =IFERROR(IF($A13=$A12,($I13-$I12)/($B13-$B12),""),"null") -> 0.21877144 | T12: =IFERROR(IF($A13=$A12,($M13-$M12)/($B13-$B12),""),"null") -> 0.3046367 | U12: =IFERROR(ROUND(E12,0),"null") -> 54 | V12: =IFERROR(ROUND(I12,0),"null") -> 27 | W12: =IFERROR(ROUND(M12,0),"null") -> 70 | X12: =IF(AND($A13=$A12,$U12=100,$U13=100),"fullaccesss","") | Y12: =IF(AND($A13=$A12,$V12=100,$V13=100),"fullaccesss","") | Z12: =IF(AND($A13=$A12,$W12=100,$W13=100),"fullaccesss","") | AA12: =IFERROR(IF(AND(S12<>"",T12<>""),S12-T12,""),"null") -> -0.085865258
A13: Angola | B13: 2020 | C13: 32866.27 | D13: 66.824997 | E13: 57.167738 | F13: 9.2873499 | G13: 19.450825 | H13: 14.094087 | I13: 27.808227 | J13: 8.7404884 | K13: 22.933153 | L13: 40.518132 | M13: 71.743149 | N13: 9.5588375 | O13: 17.722035 | P13: 0.97597916 | Q13: =IF(A14=A13,B14-B13,"") | R13: =IFERROR(IF($A14=$A13,($E14-$E13)/($B14-$B13),""),"null") | S13: =IFERROR(IF($A14=$A13,($I14-$I13)/($B14-$B13),""),"null") | T13: =IFERROR(IF($A14=$A13,($M14-$M13)/($B14-$B13),""),"null") | U13: =IFERROR(ROUND(E13,0),"null") -> 57 | V13: =IFERROR(ROUND(I13,0),"null") -> 28 | W13: =IFERROR(ROUND(M13,0),"null") -> 72 | X13: =IF(AND($A14=$A13,$U13=100,$U14=100),"fullaccesss","") | Y13: =IF(AND($A14=$A13,$V13=100,$V14=100),"fullaccesss","") | Z13: =IF(AND($A14=$A13,$W13=100,$W14=100),"fullaccesss","") | AA13: =IFERROR(IF(AND(S13<>"",T13<>""),S13-T13,""),"null")
A14: Anguilla | B14: 2015 | C14: 14.279 | D14: 100 | E14: 97.482274 | F14: 0 | G14: 2.5177258 | H14: 0 | I14: null | J14: null | K14: null | L14: null | M14: 97.482274 | N14: 0 | O14: 2.5177258 | P14: 0 | Q14: =IF(A15=A14,B15-B14,"") -> 2 | R14: =IFERROR(IF($A15=$A14,($E15-$E14)/($B15-$B14),""),"null") -> 0 | S14: =IFERROR(IF($A15=$A14,($I15-$I14)/($B15-$B14),""),"null") -> null | T14: =IFERROR(IF($A15=$A14,($M15-$M14)/($B15-$B14),""),"null") -> 0 | U14: =IFERROR(ROUND(E14,0),"null") -> 97 | V14: =IFERROR(ROUND(I14,0),"null") -> null | W14: =IFERROR(ROUND(M14,0),"null") -> 97 | X14: =IF(AND($A15=$A14,$U14=100,$U15=100),"fullaccesss","") | Y14: =IF(AND($A15=$A14,$V14=100,$V15=100),"fullaccesss","") | Z14: =IF(AND($A15=$A14,$W14=100,$W15=100),"fullaccesss","") | AA14: =IFERROR(IF(AND(S14<>"",T14<>""),S14-T14,""),"null") -> null
A15: Anguilla | B15: 2017 | C15: 14.588 | D15: 100 | E15: 97.482274 | F15: 0 | G15: 2.5177258 | H15: 0 | I15: null | J15: null | K15: null | L15: null | M15: 97.482274 | N15: 0 | O15: 2.5177258 | P15: 0 | Q15: =IF(A16=A15,B16-B15,"") | R15: =IFERROR(IF($A16=$A15,($E16-$E15)/($B16-$B15),""),"null") | S15: =IFERROR(IF($A16=$A15,($I16-$I15)/($B16-$B15),""),"null") | T15: =IFERROR(IF($A16=$A15,($M16-$M15)/($B16-$B15),""),"null") | U15: =IFERROR(ROUND(E15,0),"null") -> 97 | V15: =IFERROR(ROUND(I15,0),"null") -> null | W15: =IFERROR(ROUND(M15,0),"null") -> 97 | X15: =IF(AND($A16=$A15,$U15=100,$U16=100),"fullaccesss","") | Y15: =IF(AND($A16=$A15,$V15=100,$V16=100),"fullaccesss","") | Z15: =IF(AND($A16=$A15,$W15=100,$W16=100),"fullaccesss","") | AA15: =IFERROR(IF(AND(S15<>"",T15<>""),S15-T15,""),"null")
A16: Antigua and Barbuda | B16: 2015 | C16: 93.570999 | D16: 25 | E16: 96.739186 | F16: 0 | G16: 3.1663476 | H16: 0.094466114 | I16: null | J16: null | K16: null | L16: null | M16: null | N16: null | O16: null | P16: null | Q16: =IF(A17=A16,B17-B16,"") -> 2 | R16: =IFERROR(IF($A17=$A16,($E17-$E16)/($B17-$B16),""),"null") -> 0 | S16: =IFERROR(IF($A17=$A16,($I17-$I16)/($B17-$B16),""),"null") -> null | T16: =IFERROR(IF($A17=$A16,($M17-$M16)/($B17-$B16),""),"null") -> null | U16: =IFERROR(ROUND(E16,0),"null") -> 97 | V16: =IFERROR(ROUND(I16,0),"null") -> null | W16: =IFERROR(ROUND(M16,0),"null") -> null | X16: =IF(AND($A17=$A16,$U16=100,$U17=100),"fullaccesss","") | Y16: =IF(AND($A17=$A16,$V16=100,$V17=100),"fullaccesss","") | Z16: =IF(AND($A17=$A16,$W16=100,$W17=100),"fullaccesss","") | AA16: =IFERROR(IF(AND(S16<>"",T16<>""),S16-T16,""),"null") -> null
A17: Antigua and Barbuda | B17: 2017 | C17: 95.425003 | D17: 24.713001 | E17: 96.739186 | F17: 0 | G17: 3.1663476 | H17: 0.094466114 | I17: null | J17: null | K17: null | L17: null | M17: null | N17: null | O17: null | P17: null | Q17: =IF(A18=A17,B18-B17,"") | R17: =IFERROR(IF($A18=$A17,($E18-$E17)/($B18-$B17),""),"null") | S17: =IFERROR(IF($A18=$A17,($I18-$I17)/($B18-$B17),""),"null") | T17: =IFERROR(IF($A18=$A17,($M18-$M17)/($B18-$B17),""),"null") | U17: =IFERROR(ROUND(E17,0),"null") -> 97 | V17: =IFERROR(ROUND(I17,0),"null") -> null | W17: =IFERROR(ROUND(M17,0),"null") -> null | X17: =IF(AND($A18=$A17,$U17=100,$U18=100),"fullaccesss","") | Y17: =IF(AND($A18=$A17,$V17=100,$V18=100),"fullaccesss","") | Z17: =IF(AND($A18=$A17,$W17=100,$W18=100),"fullaccesss","") | AA17: =IFERROR(IF(AND(S17<>"",T17<>""),S17-T17,""),"null")
A18: Argentina | B18: 2015 | C18: 43075.414 | D18: 91.502998 | E18: 98.966588 | F18: 0 | G18: 0.66491438 | H18: 0.36849747 | I18: 92.98366 | J18: 0 | K18: 2.6795449 | L18: 4.3367951 | M18: 99.522163 | N18: 0 | O18: 0.47783695 | P18: 0 | Q18: =IF(A19=A18,B19-B18,"") -> 5 | R18: =IFERROR(IF($A19=$A18,($E19-$E18)/($B19-$B18),""),"null") -> null | S18: =IFERROR(IF($A19=$A18,($I19-$I18)/($B19-$B18),""),"null") -> null | T18: =IFERROR(IF($A19=$A18,($M19-$M18)/($B19-$B18),""),"null") -> 0.05365152 | U18: =IFERROR(ROUND(E18,0),"null") -> 99 | V18: =IFERROR(ROUND(I18,0),"null") -> 93 | W18: =IFERROR(ROUND(M18,0),"null") -> 100 | X18: =IF(AND($A19=$A18,$U18=100,$U19=100),"fullaccesss","") | Y18: =IF(AND($A19=$A18,$V18=100,$V19=100),"fullaccesss","") | Z18: =IF(AND($A19=$A18,$W18=100,$W19=100),"fullaccesss","") -> fullaccesss | AA18: =IFERROR(IF(AND(S18<>"",T18<>""),S18-T18,""),"null") -> null
A19: Argentina | B19: 2020 | C19: 45195.777 | D19: 92.111 | E19: null | F19: null | G19: null | H19: null | I19: null | J19: null | K19: null | L19: null | M19: 99.790421 | N19: 0 | O19: 0.20957935 | P19: 0 | Q19: =IF(A20=A19,B20-B19,"") | R19: =IFERROR(IF($A20=$A19,($E20-$E19)/($B20-$B19),""),"null") | S19: =IFERROR(IF($A20=$A19,($I20-$I19)/($B20-$B19),""),"null") | T19: =IFERROR(IF($A20=$A19,($M20-$M19)/($B20-$B19),""),"null") | U19: =IFERROR(ROUND(E19,0),"null") -> null | V19: =IFERROR(ROUND(I19,0),"null") -> null | W19: =IFERROR(ROUND(M19,0),"null") -> 100 | X19: =IF(AND($A20=$A19,$U19=100,$U20=100),"fullaccesss","") | Y19: =IF(AND($A20=$A19,$V19=100,$V20=100),"fullaccesss","") | Z19: =IF(AND($A20=$A19,$W19=100,$W20=100),"fullaccesss","") | AA19: =IFERROR(IF(AND(S19<>"",T19<>""),S19-T19,""),"null")
A20: Armenia | B20: 2015 | C20: 2925.5591 | D20: 63.085003 | E20: 99.552567 | F20: 0 | G20: 0.098505084 | H20: 0.34892822 | I20: 99.054779 | J20: 0 | K20: 0 | L20: 0.94522073 | M20: 99.843853 | N20: 0 | O20: 0.1561466 | P20: 0 | Q20: =IF(A21=A20,B21-B20,"") -> 5 | R20: =IFERROR(IF($A21=$A20,($E21-$E20)/($B21-$B20),""),"null") -> 0.083722798 | S20: =IFERROR(IF($A21=$A20,($I21-$I20)/($B21-$B20),""),"null") -> 0.18904415 | T20: =IFERROR(IF($A21=$A20,($M21-$M20)/($B21-$B20),""),"null") -> 0.022125564 | U20: =IFERROR(ROUND(E20,0),"null") -> 100 | V20: =IFERROR(ROUND(I20,0),"null") -> 99 | W20: =IFERROR(ROUND(M20,0),"null") -> 100 | X20: =IF(AND($A21=$A20,$U20=100,$U21=100),"fullaccesss","") -> fullaccesss | Y20: =IF(AND($A21=$A20,$V20=100,$V21=100),"fullaccesss","") | Z20: =IF(AND($A21=$A20,$W20=100,$W21=100),"fullaccesss","") -> fullaccesss | AA20: =IFERROR(IF(AND(S20<>"",T20<>""),S20-T20,""),"null") -> 0.16691858
A21: Armenia | B21: 2020 | C21: 2963.2339 | D21: 63.313 | E21: 99.971181 | F21: 0 | G21: 0.028819308 | H21: 0 | I21: 100 | J21: 0 | K21: 0 | L21: 0 | M21: 99.954481 | N21: 0 | O21: 0.045518784 | P21: 0 | Q21: =IF(A22=A21,B22-B21,"") | R21: =IFERROR(IF($A22=$A21,($E22-$E21)/($B22-$B21),""),"null") | S21: =IFERROR(IF($A22=$A21,($I22-$I21)/($B22-$B21),""),"null") | T21: =IFERROR(IF($A22=$A21,($M22-$M21)/($B22-$B21),""),"null") | U21: =IFERROR(ROUND(E21,0),"null") -> 100 | V21: =IFERROR(ROUND(I21,0),"null") -> 100 | W21: =IFERROR(ROUND(M21,0),"null") -> 100 | X21: =IF(AND($A22=$A21,$U21=100,$U22=100),"fullaccesss","") | Y21: =IF(AND($A22=$A21,$V21=100,$V22=100),"fullaccesss","") | Z21: =IF(AND($A22=$A21,$W21=100,$W22=100),"fullaccesss","") | AA21: =IFERROR(IF(AND(S21<>"",T21<>""),S21-T21,""),"null")
A22: Aruba | B22: 2015 | C22: 104.339 | D22: 43.108002 | E22: 97.869023 | F22: 0 | G22: 1.9599362 | H22: 0.17104041 | I22: null | J22: null | K22: null | L22: null | M22: null | N22: null | O22: null | P22: null | Q22: =IF(A23=A22,B23-B22,"") -> 1 | R22: =IFERROR(IF($A23=$A22,($E23-$E22)/($B23-$B22),""),"null") -> 0 | S22: =IFERROR(IF($A23=$A22,($I23-$I22)/($B23-$B22),""),"null") -> null | T22: =IFERROR(IF($A23=$A22,($M23-$M22)/($B23-$B22),""),"null") -> null | U22: =IFERROR(ROUND(E22,0),"null") -> 98 | V22: =IFERROR(ROUND(I22,0),"null") -> null | W22: =IFERROR(ROUND(M22,0),"null") -> null | X22: =IF(AND($A23=$A22,$U22=100,$U23=100),"fullaccesss","") | Y22: =IF(AND($A23=$A22,$V22=100,$V23=100),"fullaccesss","") | Z22: =IF(AND($A23=$A22,$W22=100,$W23=100),"fullaccesss","") | AA22: =IFERROR(IF(AND(S22<>"",T22<>""),S22-T22,""),"null") -> null
A23: Aruba | B23: 2016 | C23: 104.865 | D23: 43.191998 | E23: 97.869023 | F23: 0 | G23: 1.9599362 | H23: 0.17104041 | I23: null | J23: null | K23: null | L23: null | M23: null | N23: null | O23: null | P23: null | Q23: =IF(A24=A23,B24-B23,"") | R23: =IFERROR(IF($A24=$A23,($E24-$E23)/($B24-$B23),""),"null") | S23: =IFERROR(IF($A24=$A23,($I24-$I23)/($B24-$B23),""),"null") | T23: =IFERROR(IF($A24=$A23,($M24-$M23)/($B24-$B23),""),"null") | U23: =IFERROR(ROUND(E23,0),"null") -> 98 | V23: =IFERROR(ROUND(I23,0),"null") -> null | W23: =IFERROR(ROUND(M23,0),"null") -> null | X23: =IF(AND($A24=$A23,$U23=100,$U24=100),"fullaccesss","") | Y23: =IF(AND($A24=$A23,$V23=100,$V24=100),"fullaccesss","") | Z23: =IF(AND($A24=$A23,$W23=100,$W24=100),"fullaccesss","") | AA23: =IFERROR(IF(AND(S23<>"",T23<>""),S23-T23,""),"null")
A24: Australia | B24: 2015 | C24: 23932.498 | D24: 85.701004 | E24: 99.970006 | F24: 0 | G24: 0.029994331 | H24: 0 | I24: 100 | J24: 0 | K24: 0 | L24: 0 | M24: 99.965 | N24: 0 | O24: 0.035 | P24: 0 | Q24: =IF(A25=A24,B25-B24,"") -> 5 | R24: =IFERROR(IF($A25=$A24,($E25-$E24)/($B25-$B24),""),"null") -> -3.877e-05 | S24: =IFERROR(IF($A25=$A24,($I25-$I24)/($B25-$B24),""),"null") -> 0 | T24: =IFERROR(IF($A25=$A24,($M25-$M24)/($B25-$B24),""),"null") -> 0 | U24: =IFERROR(ROUND(E24,0),"null") -> 100 | V24: =IFERROR(ROUND(I24,0),"null") -> 100 | W24: =IFERROR(ROUND(M24,0),"null") -> 100 | X24: =IF(AND($A25=$A24,$U24=100,$U25=100),"fullaccesss","") -> fullaccesss | Y24: =IF(AND($A25=$A24,$V24=100,$V25=100),"fullaccesss","") -> fullaccesss | Z24: =IF(AND($A25=$A24,$W24=100,$W25=100),"fullaccesss","") -> fullaccesss | AA24: =IFERROR(IF(AND(S24<>"",T24<>""),S24-T24,""),"null") -> 0
